2019-04-29 14:48:22,347 - __main__ - ERROR - cmdGetLink cannot be unloaded. [Extension 'cmdGetLink' has not been loaded.]
Traceback (most recent call last):
  File "f:\_DEV\Discord\SnakeBot\__main__.py", line 64, in unload
    bot.unload_extension(extension)
  File "F:\_DEV\Envs\SnakeBot\lib\site-packages\discord\ext\commands\bot.py", line 650, in unload_extension
    raise errors.ExtensionNotLoaded(name)
discord.ext.commands.errors.ExtensionNotLoaded: Extension 'cmdGetLink' has not been loaded.
2019-04-29 14:48:41,076 - __main__ - ERROR - cmdGetLink cannot be loaded. [Extension 'cmdGetLink' could not be loaded.]
Traceback (most recent call last):
  File "F:\_DEV\Envs\SnakeBot\lib\site-packages\discord\ext\commands\bot.py", line 618, in load_extension
    lib = importlib.import_module(name)
  File "F:\_DEV\Envs\SnakeBot\lib\importlib\__init__.py", line 126, in import_module
    return _bootstrap._gcd_import(name[level:], package, level)
  File "<frozen importlib._bootstrap>", line 978, in _gcd_import
  File "<frozen importlib._bootstrap>", line 961, in _find_and_load
  File "<frozen importlib._bootstrap>", line 948, in _find_and_load_unlocked
ModuleNotFoundError: No module named 'cmdGetLink'

The above exception was the direct cause of the following exception:

Traceback (most recent call last):
  File "f:\_DEV\Discord\SnakeBot\__main__.py", line 53, in load
    bot.load_extension(extension)
  File "F:\_DEV\Envs\SnakeBot\lib\site-packages\discord\ext\commands\bot.py", line 620, in load_extension
    raise errors.ExtensionNotFound(name, e) from e
discord.ext.commands.errors.ExtensionNotFound: Extension 'cmdGetLink' could not be loaded.
2019-04-29 15:52:51,141 - db_handler - ERROR - Get allycode is FAILED. 'str' object has no attribute 'formant'
Traceback (most recent call last):
  File "f:\_DEV\Discord\SnakeBot\db_handler.py", line 116, in get_allycode
    self.logger.info('{} found for {}'.formant(self.allycode, self.user_id))
AttributeError: 'str' object has no attribute 'formant'
2019-04-29 15:52:51,806 - swgoh_handler - ERROR - GET url is failed - [Expecting value: line 2 column 1 (char 1)]
Traceback (most recent call last):
  File "f:\_DEV\Discord\SnakeBot\swgoh_handler.py", line 25, in swgoh_getuser
    return json.loads(self.response.text)
  File "d:\python3.6-64\Lib\json\__init__.py", line 354, in loads
    return _default_decoder.decode(s)
  File "d:\python3.6-64\Lib\json\decoder.py", line 339, in decode
    obj, end = self.raw_decode(s, idx=_w(s, 0).end())
  File "d:\python3.6-64\Lib\json\decoder.py", line 357, in raw_decode
    raise JSONDecodeError("Expecting value", s, err.value) from None
json.decoder.JSONDecodeError: Expecting value: line 2 column 1 (char 1)
2019-04-29 16:09:46,303 - db_handler - ERROR - Get allycode is FAILED. 'str' object has no attribute 'formant'
Traceback (most recent call last):
  File "f:\_DEV\Discord\SnakeBot\db_handler.py", line 116, in get_allycode
    self.logger.info('{} found for {}'.formant(self.allycode, self.user_id))
AttributeError: 'str' object has no attribute 'formant'
2019-04-29 16:20:02,150 - discord.client - ERROR - Attempting a reconnect in 0.84s
Traceback (most recent call last):
  File "F:\_DEV\Envs\SnakeBot\lib\site-packages\discord\gateway.py", line 464, in poll_event
    msg = await self.recv()
  File "F:\_DEV\Envs\SnakeBot\lib\site-packages\websockets\protocol.py", line 350, in recv
    yield from self.ensure_open()
  File "F:\_DEV\Envs\SnakeBot\lib\site-packages\websockets\protocol.py", line 501, in ensure_open
    self.close_code, self.close_reason) from self.transfer_data_exc
websockets.exceptions.ConnectionClosed: WebSocket connection is closed: code = 1000 (OK), no reason

The above exception was the direct cause of the following exception:

Traceback (most recent call last):
  File "F:\_DEV\Envs\SnakeBot\lib\site-packages\discord\client.py", line 431, in connect
    await self._connect()
  File "F:\_DEV\Envs\SnakeBot\lib\site-packages\discord\client.py", line 395, in _connect
    await self.ws.poll_event()
  File "F:\_DEV\Envs\SnakeBot\lib\site-packages\discord\gateway.py", line 472, in poll_event
    raise ConnectionClosed(exc, shard_id=self.shard_id) from exc
discord.errors.ConnectionClosed: WebSocket connection is closed: code = 1000 (OK), no reason
2019-04-29 16:27:56,135 - discord.client - ERROR - Attempting a reconnect in 0.57s
Traceback (most recent call last):
  File "F:\_DEV\Envs\SnakeBot\lib\site-packages\discord\gateway.py", line 464, in poll_event
    msg = await self.recv()
  File "F:\_DEV\Envs\SnakeBot\lib\site-packages\websockets\protocol.py", line 350, in recv
    yield from self.ensure_open()
  File "F:\_DEV\Envs\SnakeBot\lib\site-packages\websockets\protocol.py", line 501, in ensure_open
    self.close_code, self.close_reason) from self.transfer_data_exc
websockets.exceptions.ConnectionClosed: WebSocket connection is closed: code = 1000 (OK), no reason

The above exception was the direct cause of the following exception:

Traceback (most recent call last):
  File "F:\_DEV\Envs\SnakeBot\lib\site-packages\discord\client.py", line 431, in connect
    await self._connect()
  File "F:\_DEV\Envs\SnakeBot\lib\site-packages\discord\client.py", line 395, in _connect
    await self.ws.poll_event()
  File "F:\_DEV\Envs\SnakeBot\lib\site-packages\discord\gateway.py", line 472, in poll_event
    raise ConnectionClosed(exc, shard_id=self.shard_id) from exc
discord.errors.ConnectionClosed: WebSocket connection is closed: code = 1000 (OK), no reason
